Workbook

Sheet Precast Design Calculations
A1: DESIGN CALCULATIONS
A3: DESCRIPTION OF THE BUILDING | B3: Symbol | C3: Value | D3: Unit | E3: Reference | F3: Kontrol / Check
A4: Lengt of the building | B4: L | C4: 36 | D4: meter
A5: Widht of the building | B5: W | C5: 24 | D5: meter
A6: Each floor height | B6: h | C6: 3.2 | D6: meter | E6: Tecnical Recuriments | F6: >2,4 meter ✓ OK
A7: Number of the floors | C7: 5 | E7: Tecnical Recuriments | F7: .=5 ✓ OK
A8: Total height of the building | C8: =C6*C7 -> 16 | D8: meter | E8: Tecnical Recuriments | F8: <24 meter ✓ OK
A9: Total area of the Floor | C9: =C4*C5 -> 864 | D9: sq meter | E9: Tecnical Recuriments | F9: 800 m²<x<1000 m² ✓ OK
A10: Atria Lengt | C10: 6
A11: Atria widht | C11: 8 | D11: sq meter
A12: Atria area | C12: =C10*C11 -> 48 | D12: sq meter
A14: ELEMENTS GEOMETRY AND VALUES
A15: Column width ( 40 cm x 40 cm ) | C15: 40 | D15: cm | E15: CRH Catalog
A16: Column depth ( 40 cm x 40 cm ) | C16: 40 | D16: cm
A17: Beam width ( 24cm x 36cm ) | C17: 24 | D17: cm | E17: CRH Catalog RB 24/36
A18: Beam depth ( 24cm x 36cm ) | C18: 36 | D18: cm | E18: CRH Catalog RB 24/36
A19: Hollow core width (120cmx27cm) | C19: 120 | D19: cm | E19: CRH Catalog JE 270 | F19: Ground floor, office area
A20: Hollow core depth (120cmx27cm) | B20: h,bj | C20: 27 | D20: cm | E20: CRH Catalog JE 270 | F20: Ground floor, office area
A21: Hollow core depth (120cmx22cm) | E21: CRH Catalog DB 220 | F21: roof and residental area
A30: IMPOSED LOADS
A31: Basement Floor | C31: 4 | D31: kN/m2 | E31: EN/DS 1991-1-1 DK Tab. 6.2 Category D1
A32: Ground Floor | C32: 4 | D32: kN/m2 | E32: EN/DS 1991-1-1 DK Tab. 6.2 Category D1
A33: 2nd & 3rd floor - offices | C33: 2.5 | D33: kN/m2 | E33: EN/DS 1991-1-1 DK Tab. 6.2 Category B
A34: `+ moveable partiton wall | C34: 0.8 | D34: kN/m2 | E34: EN 1991-1-1 6.5.3.1 | F34: qk ​=max{0.35kN/m2, (0.4/m)x​ (Qk)​} assume 10 cm ytong 2 kN/m
A35: Offices total imposed load | C35: =C33+C34 -> 3.3 | D35: kN/m2
A36: 4th floor - residential | C36: 1.5 | D36: kN/m2 | E36: EN/DS 1991-1-1 DK Tab. 6.2 Category A1
A37: Roof | C37: 0.4 | D37: kN/m2 | E37: EN 1991-1-1 Tab. 6.2 Catagori H
A40: NATURAL LOADS ON ROOF
A41: Snow Calculation
A42: Characteristic ground snow load in Denmark, sk | C42: 1 | D42: kN/m2 | E42: EN 1991-1-3 National Annex 4.1.(1)
A43: Flat roof μ1​=0.8Ce,F​ | C43: 0.8 | E43: EN 1991-1- 3 7.5.2 | F43: L=38 m , W =24 m Lc​=2W−(L)^2 /W =32,85 m Lc​≤50m Ce,F​=Ce​ | G43: Terrain Catagory 3 ce normal b
A44: Exposure Coefficient Normal ( Ce) | C44: 1 | E44: EN 1991-1- 3 7.3 | F44: Terrain Catagory 3
A45: Termal Coefficient Normal | C45: 1 | E45: EN 1991-1- 3 7.4 | F45: Good isolated building Artias glass roof is not considered
A46: Snow Load s=μ1x​Ct​xsk​ | C46: 0.8 | D46: kN/m2 | E46: EN 1991-1- 3 7.2
A47: Wind Calculation
A48: Location Copenhagen (Assumption) | B48: Vb,0 | C48: 24 | D48: m/s | E48: EN 1991-1-4 DK NATIONAL ANEX 4.2.1 | F48: Basic wind speed over all Copenhagen area
A49: Terrain Catagory 3 | E49: Tecnical Recuriments
A51: Wind Direction | B51: cdir | C51: 1 | E51: EN 1991-1-1-4 NA table 1a | F51: There is a wind direction table on NA. We assume the worst direction and choose cdir =1
A52: C season | B52: c season | C52: 1 | E52: EN 1991-1-1-4 NA table 1b | F52: Permanent Building c season =1
A53: C probablity | B53: c prop | C53: 1 | E53: EN 1991-1-1-4 6.2 Basic Values | F53: Our projects standart design life is 50 years. And we choose c prob =1
...

Sheet ULS Combinations
A3: ROOF
A4: KFI | B4: 1 | C4: Medium consequences class
A5: ψ0 Imposed loads (H) | B5: 0
A6: ψ0 Snow/Wind | B6: 0.3
I7: LC | J7: Leading variable action | K7: Permanent load, G | L7: Imposed load, Q₁ | M7: Snow load, S | N7: Wind load, W | O7: Load combination | P7: qnet (without selfweight of hollow core ) | Q7: qnet used without selfweight
A8: Loads | B8: Value | C8: Unit | E8: Qk | F8: Value | G8: Unit | I8: 1 | J8: Imposed load leading | K8: 1.0 KFI | L8: 1.5 KFI | M8: 1.5 ψ0 KFI | N8: – | O8: =B4*B9+1.5*B4*F9+1.5*B6*F10 -> 5.25 | P8: =B4*B11+1.5*B4*F9+1.5*B6*B4*F10+1.5*B6*B4*F11 -> 2.115 | Q8: =MAX(P8:P12) -> 2.355
A9: Gk (permanent loads) | B9: =B10+B11 -> 4.29 | E9: Imposed loads | F9: ='Precast Design Calculations'!B107 -> 0.4 | G9: kn/m2 | I9: 2 | J9: Snow load leading | K9: 1.0 KFI | L9: 1.5 ψ0 KFI | M9: 1.5 KFI | N9: – | O9: =B4*B9+1.5*B5*B4*F9+1.5*B4*F10 -> 5.49 | P9: =B4*B11+1.5*B5*B4*F9+1.5*B4*F10+1.5*B6*B4*F11 -> 2.355
A10: Self-weight | B10: ='Precast Design Calculations'!B102 -> 3 | C10: kn/m2 | E10: Snow | F10: ='Precast Design Calculations'!B109 -> 0.8 | G10: kn/m2 | I10: 3 | J10: Wind load leading | K10: 1.0 KFI | L10: 1.5 ψ0 KFI | M10: 0 | N10: – | O10: =B4*B9+1.5*B5*B4*F9+1.5*B4*F11 -> 3.84 | P10: =B4*B11+1.5*B5*B4*F9+1.5*B4*F11 -> 0.84
A11: Self-weight other | B11: ='Precast Design Calculations'!B103 -> 1.29 | C11: kn/m2 | E11: Wind | F11: ='Precast Design Calculations'!B110 -> -0.3 | G11: kn/m2 | I11: 4 | J11: Imposed load only | K11: 1.0 KFI | L11: 1.5 KFI | M11: – | N11: – | O11: =B4*B9+1.5*B4*F9 -> 4.89 | P11: =B4*B11+1.5*B4*F9 -> 1.89
I12: 5 | J12: Self weight leading | K12: 1.2 KFI | L12: 0 | M12: 0 | N12: 0 | O12: =1.2*B9 -> 5.148 | P12: =1.2*B11 -> 1.548
A15: GROUND 4 - RESIDENTIAL AREA
A16: KFI | B16: 1 | C16: Medium consequences class
A17: ψ0 Imposed loads (A) | B17: 0.5
A18: ψ0 Snow/Wind | B18: 0.3
I19: LC | J19: Leading variable action | K19: Permanent load, G | L19: Imposed load, Q₁ | M19: Snow load, S | N19: Wind load, W | O19: Load combination | P19: qnet (without selfweight of hollow core ) | Q19: qnet used without selfweight
A20: Loads | B20: Value | C20: Unit | E20: Qk | F20: Value | G20: Unit | I20: 1 | J20: Imposed load leading | K20: 1.0 KFI | L20: 1.5 KFI | M20: 1.5 ψ0 KFI | N20: 1.5 ψ0 KFI | O20: =B16*B21+1.5*B16*F21+1.5*B18*B16*F22+1.5*B18*B16*F23 -> 7.57 | P20: =B16*B23+1.5*B16*F21+1.5*B18*B16*F22+1.5*B18*B16*F23 -> 4.57 | Q20: =MAX(P20:P24) -> 4.57
A21: Gk (permanent loads) | B21: =B22+B23 -> 5.32 | C21: kn/m2 | E21: Imposed loads | F21: ='Precast Design Calculations'!B122 -> 1.5 | G21: kn/m2 | I21: 2 | J21: Snow load leading | K21: 1.0 KFI | L21: 1.5 ψ0 KFI | M21: 1.5 KFI | N21: 1.5 ψ0 KFI | O21: =B16*B21+1.5*B17*B16*F21+1.5*B16*F22+1.5*B18*B16*F23 -> 6.445 | P21: =B16*B23+1.5*B17*B16*F21+1.5*B16*F22+1.5*B18*B16*F23 -> 3.445
A22: Self-weight | B22: ='Precast Design Calculations'!B116 -> 3 | C22: kn/m2 | E22: Snow | F22: 0 | G22: kn/m2 | I22: 3 | J22: Wind load leading | K22: 1.0 KFI | L22: 1.5 ψ0 KFI | M22: 0 | N22: 1.5 KFI | O22: =B16*B21+1.5*B17*B16*F21+1.5*B16*F23 -> 6.445 | P22: =B16*B23+1.5*B17*B16*F21+1.5*B16*F23 -> 3.445
A23: Self-weight other | B23: ='Precast Design Calculations'!B117 -> 2.32 | C23: kn/m2 | E23: Wind | F23: 0 | G23: kn/m2 | I23: 4 | J23: Imposed load only | K23: 1.0 KFI | L23: 1.5 KFI | M23: – | N23: – | O23: =B16*B21+1.5*B16*F21 -> 7.57 | P23: =B16*B23+1.5*B16*F21 -> 4.57
I24: 5 | J24: Self weight leading | K24: 1.2 KFI | L24: 0 | M24: 0 | N24: 0 | O24: =1.2*B21 -> 6.384 | P24: =1.2*B23 -> 2.784
A27: GROUND 2-3 - OFFICE AREA
A28: KFI | B28: 1 | C28: Medium consequences class
A29: ψ0 Imposed loads (B) | B29: 0.6
A30: ψ0 Snow/Wind | B30: 0.3
I31: LC | J31: Leading variable action | K31: Permanent load, G | L31: Imposed load, Q₁ | M31: Snow load, S | N31: Wind load, W | O31: Load combination | P31: qnet (without selfweight of hollow core ) | Q31: qnet used without selfweight
A32: Loads | B32: Value | C32: Unit | E32: Qk | F32: Value | G32: Unit | I32: 1 | J32: Imposed load leading | K32: 1.0 KFI | L32: 1.5 KFI | M32: 1.5 ψ0 KFI | N32: 1.5 ψ0 KFI | O32: =B28*B33+1.5*B28*F33+1.5*B30*B28*F34+1.5*B30*B28*F35 -> 9.81 | P32: =B28*B35+1.5*B28*F33+1.5*B30*B28*F34+1.5*B30*B28*F35 -> 6.57 | Q32: =MAX(P32:P36) -> 6.57
A33: Gk (permanent loads) | B33: =B34+B35 -> 4.86 | C33: kn/m2 | E33: Imposed loads | F33: ='Precast Design Calculations'!B138 -> 3.3 | G33: kn/m2 | I33: 2 | J33: Snow load leading | K33: 1.0 KFI | L33: 1.5 ψ0 KFI | M33: 1.5 KFI | N33: 1.5 ψ0 KFI | O33: =B28*B33+1.5*B29*B28*F33+1.5*B28*F34+1.5*B30*B28*F35 -> 7.83 | P33: =B28*B35+1.5*B29*B28*F33+1.5*B28*F34+1.5*B30*B28*F35 -> 4.59
A34: Self-weight | B34: ='Precast Design Calculations'!B133 -> 3.24 | C34: kn/m2 | E34: Snow | F34: 0 | G34: kn/m2 | I34: 3 | J34: Wind load leading | K34: 1.0 KFI | L34: 1.5 ψ0 KFI | M34: 0 | N34: 1.5 KFI | O34: =B28*B33+1.5*B29*B28*F33+1.5*B28*F35 -> 7.83 | P34: =B28*B35+1.5*B29*B28*F33+1.5*B28*F35 -> 4.59
A35: Self-weight other | B35: ='Precast Design Calculations'!B134 -> 1.62 | C35: kn/m2 | E35: Wind | F35: 0 | G35: kn/m2 | I35: 4 | J35: Imposed load only | K35: 1.0 KFI | L35: 1.5 KFI | M35: – | N35: – | O35: =B28*B33+1.5*B28*F33 -> 9.81 | P35: =B28*B35+1.5*B28*F33 -> 6.57
I36: 5 | J36: Self weight leading | K36: 1.2 KFI | L36: 0 | M36: 0 | N36: 0 | O36: =1.2*B33 -> 5.832 | P36: =1.2*B35 -> 1.944
A39: GROUND FLOOR - COMMERCE
A40: KFI | B40: 1 | C40: Medium consequences class
A41: ψ0 Imposed loads (D) | B41: 0.6
A42: ψ0 Snow/Wind | B42: 0.3
I43: LC | J43: Leading variable action | K43: Permanent load, G | L43: Imposed load, Q₁ | M43: Snow load, S | N43: Wind load, W | O43: Load combination | P43: qnet (without selfweight of hollow core ) | Q43: qnet used without selfweight
A44: Loads | B44: Value | C44: Unit | E44: Qk | F44: Value | G44: Unit | I44: 1 | J44: Imposed load leading | K44: 1.0 KFI | L44: 1.5 KFI | M44: 1.5 ψ0 KFI | N44: 1.5 ψ0 KFI | O44: =B40*B45+1.5*B40*F45+1.5*B42*B40*F46+1.5*B42*B40*F47 -> 12.47 | P44: =B40*B47+1.5*B40*F45+1.5*B42*B40*F46+1.5*B42*B40*F47 -> 8.82 | Q44: =MAX(P44:P48) -> 8.82
A45: Gk (permanent loads) | B45: =B46+B47 -> 5.27 | C45: kn/m2 | E45: Imposed loads | F45: ='Precast Design Calculations'!B152 -> 4.8 | G45: kn/m2 | I45: 2 | J45: Snow load leading | K45: 1.0 KFI | L45: 1.5 ψ0 KFI | M45: 1.5 KFI | N45: 1.5 ψ0 KFI | O45: =B40*B45+1.5*B41*B40*F45+1.5*B40*F46+1.5*B42*B40*F47 -> 9.59 | P45: =B40*B47+1.5*B41*B40*F45+1.5*B40*F46+1.5*B42*B40*F47 -> 5.94
A46: Self-weight | B46: ='Precast Design Calculations'!B147 -> 3.65 | C46: kn/m2 | E46: Snow | F46: 0 | G46: kn/m2 | I46: 3 | J46: Wind load leading | K46: 1.0 KFI | L46: 1.5 ψ0 KFI | M46: 0 | N46: 1.5 KFI | O46: =B40*B45+1.5*B41*B40*F45+1.5*B40*F47 -> 9.59 | P46: =B40*B47+1.5*B41*B40*F45+1.5*B40*F47 -> 5.94
A47: Self-weight other | B47: ='Precast Design Calculations'!B148 -> 1.62 | C47: kn/m2 | E47: Wind | F47: 0 | G47: kn/m2 | I47: 4 | J47: Imposed load only | K47: 1.0 KFI | L47: 1.5 KFI | M47: – | N47: – | O47: =B40*B45+1.5*B40*F45 -> 12.47 | P47: =B40*B47+1.5*B40*F45 -> 8.82
I48: 5 | J48: Self weight leading | K48: 1.2 KFI | L48: 0 | M48: 0 | N48: 0 | O48: =1.2*B45 -> 6.324 | P48: =1.2*B47 -> 1.944

Sheet SLS Combinations
A1: Level | B1: SLS combination | C1: gk [kN/m2] | D1: Variable action Qk / we,k [kN/m2] | E1: Coeff. | F1: Ed [kN/m2] | G1: Formula | H1: Values without self weight of slab | I1: Max for each floor (exc. Self Weight)
A2: Basement | B2: Characteristic /Short term | C2: ='Precast Design Calculations'!B147+'Precast Design Calculations'!B148 -> 5.27 | D2: ='Precast Design Calculations'!B152 -> 4.8 | E2: 1 | F2: 10,07 | G2: Ed = gk + Qk,1 | H2: =F2-'Precast Design Calculations'!$B$147 -> 6.42 | I2: =MAX(H2:H4) -> 6.42
A3: Basement | B3: Frequent | C3: ='Precast Design Calculations'!B147+'Precast Design Calculations'!B148 -> 5.27 | D3: ='Precast Design Calculations'!B152 -> 4.8 | E3: 0.6 | F3: 8,15 | G3: Ed = gk + psi1.Qk,1 | H3: =F3-'Precast Design Calculations'!$B$147 -> 4.5
A4: Basement | B4: Quasi-permanent | C4: ='Precast Design Calculations'!B147+'Precast Design Calculations'!B148 -> 5.27 | D4: ='Precast Design Calculations'!B152 -> 4.8 | E4: 0.5 | F4: 7,67 | G4: Ed = gk + psi2.Qk,1 | H4: =F4-'Precast Design Calculations'!$B$147 -> 4.02
A5: Ground floor | B5: Characteristic | C5: ='Precast Design Calculations'!B147+'Precast Design Calculations'!B148 -> 5.27 | D5: ='Precast Design Calculations'!B152 -> 4.8 | E5: 1 | F5: 10,07 | G5: Ed = gk + Qk,1 | H5: =F5-'Precast Design Calculations'!$B$147 -> 6.42 | I5: =MAX(H5:H7) -> 6.42
A6: Ground floor | B6: Frequent | C6: ='Precast Design Calculations'!B147+'Precast Design Calculations'!B148 -> 5.27 | D6: ='Precast Design Calculations'!B152 -> 4.8 | E6: 0.6 | F6: 8,15 | G6: Ed = gk + psi1.Qk,1 | H6: =F6-'Precast Design Calculations'!$B$147 -> 4.5
A7: Ground floor | B7: Quasi-permanent | C7: ='Precast Design Calculations'!B147+'Precast Design Calculations'!B148 -> 5.27 | D7: ='Precast Design Calculations'!B152 -> 4.8 | E7: 0.5 | F7: 7,67 | G7: Ed = gk + psi2.Qk,1 | H7: =F7-'Precast Design Calculations'!$B$147 -> 4.02
A8: 2nd floor | B8: Characteristic | C8: ='Precast Design Calculations'!B133+'Precast Design Calculations'!B134 -> 4.86 | D8: ='Precast Design Calculations'!B138 -> 3.3 | E8: 1 | F8: 9,07 | G8: Ed = gk + Qk,1 | H8: =F8-'Precast Design Calculations'!$B$147 -> 5.42 | I8: =MAX(H8:H10) -> 5.42
A9: 2nd floor | B9: Frequent | C9: ='Precast Design Calculations'!B133+'Precast Design Calculations'!B134 -> 4.86 | D9: ='Precast Design Calculations'!B138 -> 3.3 | E9: 0.4 | F9: 6,79 | G9: Ed = gk + psi1.Qk,1 | H9: =F9-'Precast Design Calculations'!$B$147 -> 3.14
A10: 2nd floor | B10: Quasi-permanent | C10: ='Precast Design Calculations'!B133+'Precast Design Calculations'!B134 -> 4.86 | D10: ='Precast Design Calculations'!B138 -> 3.3 | E10: 0.2 | F10: 6,03 | G10: Ed = gk + psi2.Qk,1 | H10: =F10-'Precast Design Calculations'!$B$147 -> 2.38
A11: 3rd floor | B11: Characteristic | C11: ='Precast Design Calculations'!B133+'Precast Design Calculations'!B134 -> 4.86 | D11: ='Precast Design Calculations'!B138 -> 3.3 | E11: 1 | F11: 9,07 | G11: Ed = gk + Qk,1 | H11: =F11-'Precast Design Calculations'!$B$147 -> 5.42 | I11: =MAX(H11:H13) -> 5.42
A12: 3rd floor | B12: Frequent | C12: ='Precast Design Calculations'!B133+'Precast Design Calculations'!B134 -> 4.86 | D12: ='Precast Design Calculations'!B138 -> 3.3 | E12: 0.4 | F12: 6,79 | G12: Ed = gk + psi1.Qk,1 | H12: =F12-'Precast Design Calculations'!$B$147 -> 3.14
A13: 3rd floor | B13: Quasi-permanent | C13: ='Precast Design Calculations'!B133+'Precast Design Calculations'!B134 -> 4.86 | D13: ='Precast Design Calculations'!B138 -> 3.3 | E13: 0.2 | F13: 6,03 | G13: Ed = gk + psi2.Qk,1 | H13: =F13-'Precast Design Calculations'!$B$147 -> 2.38
A14: 4th floor | B14: Characteristic | C14: ='Precast Design Calculations'!B116+'Precast Design Calculations'!B117 -> 5.32 | D14: ='Precast Design Calculations'!B122 -> 1.5 | E14: 1 | F14: =C14+D14 -> 6.82 | G14: Ed = gk + Qk,1 | H14: =F14-'Precast Design Calculations'!$B$102 -> 3.82 | I14: =MAX(H14:H16) -> 3.82
A15: 4th floor | B15: Frequent | C15: ='Precast Design Calculations'!B116+'Precast Design Calculations'!B117 -> 5.32 | D15: ='Precast Design Calculations'!B122 -> 1.5 | E15: 0.3 | F15: =C15+E15*D15 -> 5.77 | G15: Ed = gk + psi1.Qk,1 | H15: =F15-'Precast Design Calculations'!$B$102 -> 2.77
A16: 4th floor | B16: Quasi-permanent | C16: ='Precast Design Calculations'!B116+'Precast Design Calculations'!B117 -> 5.32 | D16: ='Precast Design Calculations'!B122 -> 1.5 | E16: 0.2 | F16: =C16+E16*D16 -> 5.62 | G16: Ed = gk + psi2.Qk,1 | H16: =F16-'Precast Design Calculations'!$B$102 -> 2.62
A17: Roof | B17: Characteristic | C17: ='Precast Design Calculations'!B102+'Precast Design Calculations'!B103 -> 4.29 | D17: ='Precast Design Calculations'!B108 -> 0.4 | E17: 1 | F17: 6,03 | G17: Ed = gk + Qk,1 | H17: =F17-'Precast Design Calculations'!$B$102 -> 3.03 | I17: =MAX(H17:H19) -> 3.03
A18: Roof | B18: Frequent | C18: ='Precast Design Calculations'!B102+'Precast Design Calculations'!B103 -> 4.29 | D18: ='Precast Design Calculations'!B108 -> 0.4 | E18: 0 | F18: 4,23 | G18: Ed = gk + psi1.Qk,1 | H18: =F18-'Precast Design Calculations'!$B$102 -> 1.23
A19: Roof | B19: Quasi-permanent | C19: ='Precast Design Calculations'!B102+'Precast Design Calculations'!B103 -> 4.29 | D19: ='Precast Design Calculations'!B108 -> 0.4 | E19: 0 | F19: 4,23 | G19: Ed = gk + psi2.Qk,1 | H19: =F19-'Precast Design Calculations'!$B$102 -> 1.23

Sheet Slabs Calculations
B19: Selfweight of the Hollow Core Slabs (kN/m2) | E19: Span (m) | F19: 8
B20: -Hollow core PE 180 mm | C20: 3
B21: -Hollow core DB 220mm | C21: 3.24
B22: -Hollow core JE 270 mm | C22: 3.65
B25: qd (kN/m2) excluding the selfweight (ULS) | E25: Selection of the thickness (mm) | G25: Type manually according to the figure
B26: Ground Floor | C26: ='ULS Combinations'!Q44 -> 8.82 | E26: Ground Floor | G26: =B22 -> -Hollow core JE 270 mm
B27: 2nd Floor | C27: ='ULS Combinations'!Q32 -> 6.57 | E27: 2nd Floor | G27: =B21 -> -Hollow core DB 220mm
B28: 3rd Floor | C28: ='ULS Combinations'!Q32 -> 6.57 | E28: 3rd Floor | G28: =B21 -> -Hollow core DB 220mm
B29: 4th Floor | C29: ='ULS Combinations'!Q20 -> 4.57 | E29: 4th Floor | G29: =B20 -> -Hollow core PE 180 mm
B30: Roof | C30: ='ULS Combinations'!Q8 -> 2.355 | E30: Roof | G30: =B20 -> -Hollow core PE 180 mm

Sheet Beam Calculations
A2: Initial design of beams: | D2: Self weight of beams is excluded in this primary estimation (catalog)- but self-weight of hollow core was accounted
B4: Ground / Level | C4: m of hollow core transfering load | D4: Design load (excluding self-weight) | E4: kN/m | F4: L of beams is 6m (constant) | G4: Beam model
A6: Perimeter Beams | B6: Roof + 4 | C6: 4 | D6: ='ULS Combinations'!O20 -> 7.57 | E6: =C6*D6 -> 30.28 | G6: RB18/42
B7: Ground + 2-3 | C7: 4 | D7: ='ULS Combinations'!O44 -> 12.47 | E7: =C7*D7 -> 49.88 | G7: RB24/48
A9: Inside Beams | B9: Roof + 4 | C9: 8 | D9: ='ULS Combinations'!O20 -> 7.57 | E9: =C9*D9 -> 60.56 | G9: RB24/54
B10: Ground + 2-3 | C10: 8 | D10: ='ULS Combinations'!O44 -> 12.47 | E10: =C10*D10 -> 99.76 | G10: RB24/72
A12: Rectangular beams:

Sheet SLS Analysis
A2: Checking for Hollow Core JE 270 mm Ground Floor
A7: STEP 1 – Characteristic moment: Mk = qk × L² / 8
A8: Mk = | B8: =B12*(B10^2)/8 -> 96.672 | C8: KNm
A9: qk from SLS Short Term load | B9: ='SLS Combinations'!F2 -> 10,07 | C9: kN/m2
A10: L | B10: 8 | C10: m
A11: widht | B11: 1.2 | C11: m
A12: qk Line Load | B12: =B9*B11 -> 12.084
A13: STEP 2 – Compare Mk with catalog cracking moment
A14: Mcr =Mrev | B14: 136.2 | C14: kNm | D14: from CRH catalog
B16: 96,672 < 136,2 | C16: ✅
A17: Checking stress
A24: STEP 3 – Prestressing force: P = n × P0 | B24: Value | C24: Unit
A25: n=number of strand | B25: 6 | C25: - | D25: CRH Catalog JE 270 Slabs
A26: Ap = Strands sectional area | B26: 93 | C26: mm2 | D26: Assigment 4C Notes
A27: σ = pre stressed value | B27: 100 | C27: kN | D27: Assigment 4C Notes
A28: P | B28: =B25*B27 -> 600 | C28: kN
B30: Dimension | C30: Unit Change
A31: A – catalog area incl. joint (×10³ mm²) | B31: 189 | C31: 0.001
A32: b | B32: 270 | C32: 0.001
A33: h | B33: 1200 | C33: 0.001
A34: A | B34: =B31*C31 -> 0.189 | C34: m2 | D34: 189X10^3 mm2
A35: Void Diameter | B35: 0.185 | C35: mm
A36: Solid Cross sectional area (270x1200mm) | B36: =B32*B33*C32*C33 -> 0.324 | C36: m2
A37: Area of one void (π x d² )/4 | B37: =3.14*B35*B35/4 -> 0.026866625 | C37: m2
A38: Area of 5 void | B38: =5*B37 -> 0.13433312 | C38: m2
A39: n of voids | B39: 5
A40: Net Cross sectional area | B40: =B36-B38 -> 0.18966688 | C40: m2
A42: Mp = -N X e
A43: e | B43: 92 | C43: mm | D43: Distance from center of strands to middle of hollow core
A44: Mp = | B44: =-B28*B43*0.001 -> -55.2 | C44: kNm
A46: Mk = | B46: =B8 -> 96.672 | C46: kNm
A49: Inertia of rectangular slab according to X Axis | B49: =B33*B32^3/12 -> 1968300000 | C49: mm⁴
A50: 5 pieces voids inertia X Axis | B50: =B39*PI()*(B35*1000)^4/64 -> 2.874927e+08 | C50: mm⁴
A52: It (net) steels cross sectional area ignored. Slabs and Voids X axis accepted same checked form CRH Catalog | B52: 1681000000 | C52: mm⁴
A54: yb (270mm/2) | B54: 135 | C54: mm | E54: ½
A56: P/A | B56: =B28*1000/(B34*1000000) -> 3.1746032 | C56: MPa
A57: σn = −P/A + (Mp + Mk) × yb / I_t | B57: =-B56+(B44+B46)*1000000*B54/B52 -> 0.15598576 | C57: Mpa
A59: fctk,0.05 – C55/67, EC2 Table 3.1 [MPa] | B59: 3
A60: Check: σn ≤ fctk,0.05 | B60: =IF(B57<=B59,"✅ no cracking","❌ cracking") -> ✅ no cracking
L62: 600000 | M62: N
...

Sheet ULS Analysis
A1: Assigment C3 (b) Ultimate Design Moment Resistance | D1: For ground floor Rectangular Beam 24/72 cm
A3: Steps & Equations | B3: Value | C3: Unit | D3: Note
A4: STEP 1 – Design load vs. catalog capacity
A5: q_Ed – design load on beam | B5: ='Beam Calculations'!E10 -> 99.76 | C5: kN/m | D5: Beam Calculations – inside beam (excl. beam self-weight)
A6: q_Rd – catalog capacity at L = 6.0 m | B6: 139.12 | C6: kN/m | D6: CRH / Betonelement catalog RB 24/72 (qRd)
A7: Check: q_Ed ≤ q_Rd | B7: =IF(B5<=B6,"q_Ed ≤ q_Rd","q_Ed > q_Rd") -> q_Ed ≤ q_Rd | C7: =IF(B5<=B6,"✅","❌") -> ✅ | D7: → CRH RB24/72 can be used (8 tendons bottom, 2 top)
A9: Checking Ultimate Design Moment Resistance by hand calculation
A10: STEP 2 – Section, tendon and material data
A11: h – beam height | B11: =VALUE(MID('Beam Calculations'!G10,FIND("/",'Beam Calculations'!G10)+1,5))*10 -> 720 | C11: mm | D11: Beam Calculations (beam model RB b/h in cm)
A12: b – beam width | B12: =VALUE(MID('Beam Calculations'!G10,3,FIND("/",'Beam Calculations'!G10)-3))*10 -> 240 | C12: mm | D12: Beam Calculations (beam model RB b/h in cm)
A13: d – effective depth | B13: 650 | C13: mm | D13: CRH Catalog
A14: n – number of tendons, bottom | B14: 8 | D14: CRH Catalog (bund = 8, top = 2)
A15: A_tendon – area of 1 tendon (L12.5) | B15: 93 | C15: mm^2 | D15: Assignment C
A16: Ap = n × A_tendon | B16: =B14*B15 -> 744
A17: fck – concrete compressive strength | B17: 55 | C17: Mpa | D17: Assignment C
A18: fp0,1k – 0.1 % proof strength of tendon | B18: 1634 | C18: Mpa | D18: Assignment C / Lecture 5A Slide 14
A19: Ep – modulus of elasticity of tendon | B19: 195 | C19: Gpa | D19: Lecture 5A Slide 14
A20: εu – ultimate tendon strain | B20: 0.02 | D20: Lecture 5A Slide 14
A21: γc – partial factor, concrete | B21: 1.4 | D21: Lecture 5A Slide 15 (EC2 + DK-NA, precast)
A22: γs – partial factor, tendons | B22: 1.2 | D22: Lecture 5A Slide 15 (EC2 + DK-NA, precast)
A23: P – effective prestressing force per tendon | B23: 100 | C23: kN | D23: Given in Assignment C sheet
A25: STEP 3 – Design strengths and tendon force
A26: fcd = fck / γc | B26: =B17/B21 -> 39.285714 | C26: Mpa | D26: Design Strength Calculation
A27: fpd = fp0,1k / γs | B27: =B18/B22 -> 1361.6667 | C27: Mpa | D27: Design Strength of Prestressed Tendon
A29: Fp = Ap × fpd (tendon force at yield) | B29: =B16*B27 -> 1013080 | C29: N | D29: Total tensile force at the tendon that it can carry
A30: Fp in kN | B30: =B29/1000 -> 1013.08 | C30: kN | D30: Total tensile force in kN
A31: STEP 4 – Stress-block factors (EC2 3.1.7)
A32: λ | B32: =0.8-(B17-50)/400 -> 0.7875 | D32: Block height Lecture 5A Slide 16 (Rectangular stress block in pressure zone)
A33: η | B33: =1-(B17-50)/200 -> 0.975 | D33: Stress in the pressure block
A34: STEP 5 – Equilibrium Fc = Fp → a, x, z
A35: Fc = η × fcd × b × a | D35: Pressure Force
A36: Equilibrium: Fc = Fp
A37: → a = Fp / (η × fcd × b)
A38: a | B38: =B29/(B33*B26*B12) -> 110.20295 | C38: mm | D38: Depth of pressure zone
A39: x = a / λ | B39: =B38/B32 -> 139.94026 | C39: mm | D39: Depth of Neutral Axis
A41: z = d − a/2 | B41: =B13-(B38/2) -> 594.89852 | C41: mm | D41: Distance between Fc ( center of the block) and Fp (tendons)-Lever arm
A43: STEP 6 – Strain compatibility in the tendons
A44: εp,eff = (P / A_tendon) / Ep (initial strain) | B44: =(B23/B15)/B19 -> 0.0055141991 | D44: Strain in tendon before loading
A46: εcu3 – concrete strain (EC2 T3.1) | B46: =IF(B17<=50,0.0035,(2.6+35*((90-B17)/100)^4)/1000) -> 0.0031252187 | D46: Ultimate compressive strain of concrete from EC2 table 3.1
A48: Similar triangles: Δεp = εcu3 × (d − x) / x
...

Sheet Assignment D
A1: Assignment D1
A2: Pre Selection Column Dimensions
A14: Ground Floor Column
F29: reduction for office floor same catagory same load | H29: αn=(1 + (n-1)*ψ₀)/n
H30: n= | I30: 2
H31: ψ₀= | I31: 0.6
H32: αn= | I32: =(1+(I30-1)*I31)/I30 -> 0.8
B34: q (kN/m²) | C34: q × 8 m (kN/m) | D34: From Slabs to Beam (×6 m) | E34: Beam Self Weight | F34: R_i (kN) | G34: Ri (kN) with reduction factor
A35: Roof | B35: ='ULS Combinations'!O9 -> 5.49 | C35: =8*B35 -> 43.92 | D35: =C35*6 -> 263.52 | E35: =J42 -> 19.44 | F35: =D35+E35 -> 282.96 | G35: 282.96
A36: 4th | B36: ='ULS Combinations'!O20 -> 7.57 | C36: =8*B36 -> 60.56 | D36: =C36*6 -> 363.36 | E36: =J42 -> 19.44 | F36: =D36+E36 -> 382.8 | G36: 382.8
A37: 3rd | B37: ='ULS Combinations'!O32 -> 9.81 | C37: =8*B37 -> 78.48 | D37: =C37*6 -> 470.88 | E37: =J43 -> 25.92 | F37: =D37+E37 -> 496.8 | G37: =496.8*I32 -> 397.44
A38: 2nd | B38: ='ULS Combinations'!O32 -> 9.81 | C38: =8*B38 -> 78.48 | D38: =C38*6 -> 470.88 | E38: =J43 -> 25.92 | F38: =D38+E38 -> 496.8 | G38: =496.8*I32 -> 397.44
A39: Ground | B39: ='ULS Combinations'!O44 -> 12.47 | C39: =8*B39 -> 99.76 | D39: =C39*6 -> 598.56 | E39: =J43 -> 25.92 | F39: =D39+E39 -> 624.48 | G39: 624.48
E41: Columns weight | F41: =0.4*0.4*25*3.2*5 -> 64 | G41: 64 | I41: Selfweight of beams
I42: RB24/54 (roof+4.floor) | J42: =0.24*0.54*25*6 -> 19.44 | K42: kN
E43: Total Ri | F43: =SUM(F35:F42) -> 2347.84 | G43: =SUM(G35:G42) -> 2149.12 | I43: RB24/72 (ground Floor,2,3) | J43: =0.24*0.72*25*6 -> 25.92 | K43: kN
D45: we choose 40cm 40 cm column from the table.
A71: Connection 1 (Slabs-Beam)
A73: Joint Details Hollow Core- Beams
A92: T | B92: 40 | C92: mm | D92: Slayt 16 L>7,2 m
A93: c | B93: 75 | C93: mm | D93: CRH Catalog
A94: a min | B94: 18.33 | C94: mm
A95: a0 | B95: 37.5 | C95: mm
A96: amax | B96: 63.3 | C96: mm
A97: e1 | B97: =120-B94 -> 101.67
A98: e2 | B98: =120-B96 -> 56.7
A132: Connection 2 (Beam Column)
A154: c | B154: 150 | C154: mm
A155: T | B155: 40 | C155: mm
A156: h= | B156: 740 | C156: mm
A157: amin= | B157: =(1/3)*B154-(1/2)*B155 -> 30
A158: amax= | B158: =(2/3*B154)+(1/2*B155) -> 120
A160: e1= | B160: =(1/2*B156-(B157)) -> 340
A161: e2= | B161: =(1/2*B156-B158) -> 250
A193: Assignment D2 Calculation
A195: a_min = 1/3·c − ½T = 1/3·150 − 20 = 30 mm
A196: a_max = 2/3·c + ½T = 2/3·150 + 20 = 120 mm
A197: ½h* = 740/2 = 370 mm
A198: e1 = ½h* − a_min = 370 − 30 = 340 mm
A199: e2 = ½h* − a_max = 370 − 120 = 250 mm
...
